Workbook

Sheet Raw_Invoice_Data
A1: Invoice_ID | B1: Vendor | C1: Item_Description | D1: Quantity | E1: Unit_Price | F1: Tax_Rate | G1: Extracted_Total
A2: INV0001 | B2: Citywide Products | C2: Files | D2: 36 | E2: 25 | F2: 0.12 | G2: 1008
A3: INV0002 | B3: Brightline Distributors | C3: Whiteboard | D3: 5 | E3: 1800 | F3: 0.18 | G3: 10620
A4: INV0003 | B4: Apex Business Solutions | C4: Files | D4: 40 | E4: 25 | F4: 0.12 | G4: 1120
A5: INV0004 | B5: Global Tech | C5: Staplers | D5: 33 | E5: 150 | F5: 0.12 | G5: 5544
A6: INV0005 | B6: Global Tech | C6: Headphones | D6: 30 | E6: 1200 | F6: 0.18 | G6: 42480
A7: INV0006 | B7: XYZ Supplies | C7: Desk | D7: 14 | E7: 5000 | F7: 0.18 | G7: 82600
A8: INV0007 | B8: Prime Office | C8: Printer Paper | D8: 30 | E8: 300 | F8: 0.18 | G8: 11120
A9: INV0008 | B9: Brightline Distributors | C9: Files | D9: 32 | E9: 25 | F9: 0.12 | G9: 896
A10: INV0009 | B10: Brightline Distributors | C10: Mouse | D10: 42 | E10: 500 | F10: 0.18 | G10: 24780
B11: Northstar Supplies | C11: Desk Lamp | D11: 15 | E11: 900 | F11: 0.18 | G11: 15930
A12: INV0011 | B12: XYZ Supplies | C12: Desk Lamp | D12: 31 | E12: 900 | F12: 0.18 | G12: 32922
A13: INV0012 | B13: Metro Wholesale | C13: Files | D13: 9 | E13: 25 | F13: 0.12 | G13: 252
A14: INV0013 | C14: Headphones | D14: 44 | E14: 1200 | F14: 0.18 | G14: 62304
A15: INV0014 | B15: Metro Wholesale | C15: Folders | D15: 26 | E15: 35 | F15: 0.12 | G15: 1019.2
A16: INV0015 | B16: Global Tech | C16: Desk Lamp | D16: 6 | E16: 900 | F16: 0.18 | G16: 6372
A17: INV0016 | B17: Northstar Supplies | C17: Desk Lamp | D17: 2 | E17: 900 | F17: 0.18 | G17: 2124
A18: INV0017 | B18: Evergreen Retail | C18: Files | D18: 36 | E18: 25 | F18: 0.12 | G18: 1008
A19: INV0018 | B19: XYZ Supplies | C19: USB Drive | D19: 3 | E19: 450 | F19: 0.18 | G19: 1593
A20: INV0019 | B20: Brightline Distributors | C20: USB Drive | D20: 2 | E20: 450 | F20: 0.18 | G20: 1312
A21: INV0020 | B21: Citywide Products | C21: Keyboards | D21: 4 | E21: 800 | F21: 0.18 | G21: 3776
A22: INV0021 | B22: Northstar Supplies | C22: Monitor | D22: 19 | E22: 6500 | F22: 0.18 | G22: 145730
A23: INV0022 | B23: XYZ Supplies | C23: Keyboards | D23: 27 | E23: 800 | F23: 0.18 | G23: 25488
A24: INV0023 | B24: Brightline Distributors | C24: Paper Clips | D24: 32 | E24: 60 | F24: 0.12 | G24: 2150.4
A25: INV0024 | B25: Prime Office | C25: Printer Toner | D25: 0 | E25: 2200 | F25: 0.18 | G25: 88264
A26: INV0025 | B26: Metro Wholesale | C26: Monitor | D26: 46 | E26: 6500 | F26: 0.18 | G26: 352820
... A31: INV0030 | B31: Evergreen Retail | C31: Keyboards | D31: 45 | E31: 800 | F31: 0.18 | G31: 42480
B32: Prime Office | D32: 49 | E32: 25 | F32: 0.12 | G32: 1372
A33: INV0032 | B33: Apex Business Solutions | C33: Whiteboard | D33: 10 | E33: 1800 | F33: 0.18 | G33: 21240
A34: INV0033 | B34: XYZ Supplies | C34: Keyboards | D34: 21 | E34: 800 | F34: 0.18 | G34: 19824
A35: INV0034 | B35: Brightline Distributors | C35: Folders | D35: 6 | E35: 35 | F35: 0.12 | G35: 235.2
A36: INV0035 | B36: ABC Traders | C36: Extension Board | D36: 37 | E36: 550 | F36: 0.18 | G36: 24013
A37: INV0036 | B37: Brightline Distributors | C37: Whiteboard | D37: 5 | E37: 1800 | F37: 0.18 | G37: 10720
A38: INV0037 | B38: Metro Wholesale | C38: Headphones | D38: 7 | E38: 1200 | F38: 0.18 | G38: 9912
A39: INV0038 | B39: Metro Wholesale | C39: Keyboards | D39: 18 | E39: 800 | F39: 0.18 | G39: 16992
A40: INV0039 | B40: Evergreen Retail | C40: Files | D40: 29 | E40: 25 | F40: 0.12 | G40: 812
A41: INV0040 | B41: XYZ Supplies | C41: Calculator | D41: 22 | E41: 650 | F41: 0.18 | G41: 16874
A42: INV0041 | B42: Global Tech | C42: Pens | D42: 19 | E42: 10 | F42: 0.18 | G42: 224.2
A43: INV0042 | C43: Office Chairs | D43: 2 | E43: 2500 | F43: 0.18 | G43: 5900
A44: INV0043 | B44: Northstar Supplies | C44: Filing Cabinet | D44: 31 | E44: 7200 | F44: 0.18 | G44: 263376
...

Sheet tbl_invoices
A1: Invoice_ID | B1: Vendor | C1: Item_Description | D1: Quantity | E1: Unit_Price | F1: Tax_Rate | G1: Extracted_Total | H1: Subtotal | I1: Expected_Tax | J1: Expected_total | K1: Difference | L1: Verification_status | M1: Data_quality_status | N1: Duplicate_check | O1: Final QC status
A2: INV0001 | B2: Citywide Products | C2: Files | D2: 36 | E2: 25 | F2: 0.12 | G2: 1008 | H2: =D2*E2 -> 900 | I2: =H2*F2 -> 108 | J2: =H2+I2 -> 1008 | K2: =G2-J2 -> 0 | L2: =IF(K2=0,"Verified","Discrepancy") -> Verified | M2: =IF(OR(A2="",B2="",C2="",D2<=0,E2<=0),"Review Required","Complete") -> Complete | N2: =IF(A2="","Missing Invoice ID",IF(COUNTIF($A$2:$A$151,A2)>1,"Duplicate","Unique")) -> Unique | O2: =IF(OR(A2="",N2="Missing Invoice ID"),"Missing Invoice ID",IF(N2="Duplicate","Duplicate - Investigate",IF(M2="Review Required","Incomplete - Review",IF(L2="Discrepancy","Amount Mismatch","Passed QC")))) -> Passed QC
A3: INV0002 | B3: Brightline Distributors | C3: Whiteboard | D3: 5 | E3: 1800 | F3: 0.18 | G3: 10620 | H3: =D3*E3 -> 9000 | I3: =H3*F3 -> 1620 | J3: =H3+I3 -> 10620 | K3: =G3-J3 -> 0 | L3: =IF(K3=0,"Verified","Discrepancy") -> Verified | M3: =IF(OR(A3="",B3="",C3="",D3<=0,E3<=0),"Review Required","Complete") -> Complete | N3: =IF(A3="","Missing Invoice ID",IF(COUNTIF($A$2:$A$151,A3)>1,"Duplicate","Unique")) -> Unique | O3: =IF(OR(A3="",N3="Missing Invoice ID"),"Missing Invoice ID",IF(N3="Duplicate","Duplicate - Investigate",IF(M3="Review Required","Incomplete - Review",IF(L3="Discrepancy","Amount Mismatch","Passed QC")))) -> Passed QC
A4: INV0003 | B4: Apex Business Solutions | C4: Files | D4: 40 | E4: 25 | F4: 0.12 | G4: 1120 | H4: =D4*E4 -> 1000 | I4: =H4*F4 -> 120 | J4: =H4+I4 -> 1120 | K4: =G4-J4 -> 0 | L4: =IF(K4=0,"Verified","Discrepancy") -> Verified | M4: =IF(OR(A4="",B4="",C4="",D4<=0,E4<=0),"Review Required","Complete") -> Complete | N4: =IF(A4="","Missing Invoice ID",IF(COUNTIF($A$2:$A$151,A4)>1,"Duplicate","Unique")) -> Unique | O4: =IF(OR(A4="",N4="Missing Invoice ID"),"Missing Invoice ID",IF(N4="Duplicate","Duplicate - Investigate",IF(M4="Review Required","Incomplete - Review",IF(L4="Discrepancy","Amount Mismatch","Passed QC")))) -> Passed QC
A5: INV0004 | B5: Global Tech | C5: Staplers | D5: 33 | E5: 150 | F5: 0.12 | G5: 5544 | H5: =D5*E5 -> 4950 | I5: =H5*F5 -> 594 | J5: =H5+I5 -> 5544 | K5: =G5-J5 -> 0 | L5: =IF(K5=0,"Verified","Discrepancy") -> Verified | M5: =IF(OR(A5="",B5="",C5="",D5<=0,E5<=0),"Review Required","Complete") -> Complete | N5: =IF(A5="","Missing Invoice ID",IF(COUNTIF($A$2:$A$151,A5)>1,"Duplicate","Unique")) -> Unique | O5: =IF(OR(A5="",N5="Missing Invoice ID"),"Missing Invoice ID",IF(N5="Duplicate","Duplicate - Investigate",IF(M5="Review Required","Incomplete - Review",IF(L5="Discrepancy","Amount Mismatch","Passed QC")))) -> Passed QC
A6: INV0005 | B6: Global Tech | C6: Headphones | D6: 30 | E6: 1200 | F6: 0.18 | G6: 42480 | H6: =D6*E6 -> 36000 | I6: =H6*F6 -> 6480 | J6: =H6+I6 -> 42480 | K6: =G6-J6 -> 0 | L6: =IF(K6=0,"Verified","Discrepancy") -> Verified | M6: =IF(OR(A6="",B6="",C6="",D6<=0,E6<=0),"Review Required","Complete") -> Complete | N6: =IF(A6="","Missing Invoice ID",IF(COUNTIF($A$2:$A$151,A6)>1,"Duplicate","Unique")) -> Unique | O6: =IF(OR(A6="",N6="Missing Invoice ID"),"Missing Invoice ID",IF(N6="Duplicate","Duplicate - Investigate",IF(M6="Review Required","Incomplete - Review",IF(L6="Discrepancy","Amount Mismatch","Passed QC")))) -> Passed QC
A7: INV0006 | B7: XYZ Supplies | C7: Desk | D7: 14 | E7: 5000 | F7: 0.18 | G7: 82600 | H7: =D7*E7 -> 70000 | I7: =H7*F7 -> 12600 | J7: =H7+I7 -> 82600 | K7: =G7-J7 -> 0 | L7: =IF(K7=0,"Verified","Discrepancy") -> Verified | M7: =IF(OR(A7="",B7="",C7="",D7<=0,E7<=0),"Review Required","Complete") -> Complete | N7: =IF(A7="","Missing Invoice ID",IF(COUNTIF($A$2:$A$151,A7)>1,"Duplicate","Unique")) -> Unique | O7: =IF(OR(A7="",N7="Missing Invoice ID"),"Missing Invoice ID",IF(N7="Duplicate","Duplicate - Investigate",IF(M7="Review Required","Incomplete - Review",IF(L7="Discrepancy","Amount Mismatch","Passed QC")))) -> Passed QC
A8: INV0007 | B8: Prime Office | C8: Printer Paper | D8: 30 | E8: 300 | F8: 0.18 | G8: 11120 | H8: =D8*E8 -> 9000 | I8: =H8*F8 -> 1620 | J8: =H8+I8 -> 10620 | K8: =G8-J8 -> 500 | L8: =IF(K8=0,"Verified","Discrepancy") -> Discrepancy | M8: =IF(OR(A8="",B8="",C8="",D8<=0,E8<=0),"Review Required","Complete") -> Complete | N8: =IF(A8="","Missing Invoice ID",IF(COUNTIF($A$2:$A$151,A8)>1,"Duplicate","Unique")) -> Unique | O8: =IF(OR(A8="",N8="Missing Invoice ID"),"Missing Invoice ID",IF(N8="Duplicate","Duplicate - Investigate",IF(M8="Review Required","Incomplete - Review",IF(L8="Discrepancy","Amount Mismatch","Passed QC")))) -> Amount Mismatch
A9: INV0008 | B9: Brightline Distributors | C9: Files | D9: 32 | E9: 25 | F9: 0.12 | G9: 896 | H9: =D9*E9 -> 800 | I9: =H9*F9 -> 96 | J9: =H9+I9 -> 896 | K9: =G9-J9 -> 0 | L9: =IF(K9=0,"Verified","Discrepancy") -> Verified | M9: =IF(OR(A9="",B9="",C9="",D9<=0,E9<=0),"Review Required","Complete") -> Complete | N9: =IF(A9="","Missing Invoice ID",IF(COUNTIF($A$2:$A$151,A9)>1,"Duplicate","Unique")) -> Duplicate | O9: =IF(OR(A9="",N9="Missing Invoice ID"),"Missing Invoice ID",IF(N9="Duplicate","Duplicate - Investigate",IF(M9="Review Required","Incomplete - Review",IF(L9="Discrepancy","Amount Mismatch","Passed QC")))) -> Duplicate - Investigate
A10: INV0009 | B10: Brightline Distributors | C10: Mouse | D10: 42 | E10: 500 | F10: 0.18 | G10: 24780 | H10: =D10*E10 -> 21000 | I10: =H10*F10 -> 3780 | J10: =H10+I10 -> 24780 | K10: =G10-J10 -> 0 | L10: =IF(K10=0,"Verified","Discrepancy") -> Verified | M10: =IF(OR(A10="",B10="",C10="",D10<=0,E10<=0),"Review Required","Complete") -> Complete | N10: =IF(A10="","Missing Invoice ID",IF(COUNTIF($A$2:$A$151,A10)>1,"Duplicate","Unique")) -> Unique | O10: =IF(OR(A10="",N10="Missing Invoice ID"),"Missing Invoice ID",IF(N10="Duplicate","Duplicate - Investigate",IF(M10="Review Required","Incomplete - Review",IF(L10="Discrepancy","Amount Mismatch","Passed QC")))) -> Passed QC
B11: Northstar Supplies | C11: Desk Lamp | D11: 15 | E11: 900 | F11: 0.18 | G11: 15930 | H11: =D11*E11 -> 13500 | I11: =H11*F11 -> 2430 | J11: =H11+I11 -> 15930 | K11: =G11-J11 -> 0 | L11: =IF(K11=0,"Verified","Discrepancy") -> Verified | M11: =IF(OR(A11="",B11="",C11="",D11<=0,E11<=0),"Review Required","Complete") -> Review Required | N11: =IF(A11="","Missing Invoice ID",IF(COUNTIF($A$2:$A$151,A11)>1,"Duplicate","Unique")) -> Missing Invoice ID | O11: =IF(OR(A11="",N11="Missing Invoice ID"),"Missing Invoice ID",IF(N11="Duplicate","Duplicate - Investigate",IF(M11="Review Required","Incomplete - Review",IF(L11="Discrepancy","Amount Mismatch","Passed QC")))) -> Missing Invoice ID
A12: INV0011 | B12: XYZ Supplies | C12: Desk Lamp | D12: 31 | E12: 900 | F12: 0.18 | G12: 32922 | H12: =D12*E12 -> 27900 | I12: =H12*F12 -> 5022 | J12: =H12+I12 -> 32922 | K12: =G12-J12 -> 0 | L12: =IF(K12=0,"Verified","Discrepancy") -> Verified | M12: =IF(OR(A12="",B12="",C12="",D12<=0,E12<=0),"Review Required","Complete") -> Complete | N12: =IF(A12="","Missing Invoice ID",IF(COUNTIF($A$2:$A$151,A12)>1,"Duplicate","Unique")) -> Unique | O12: =IF(OR(A12="",N12="Missing Invoice ID"),"Missing Invoice ID",IF(N12="Duplicate","Duplicate - Investigate",IF(M12="Review Required","Incomplete - Review",IF(L12="Discrepancy","Amount Mismatch","Passed QC")))) -> Passed QC
A13: INV0012 | B13: Metro Wholesale | C13: Files | D13: 9 | E13: 25 | F13: 0.12 | G13: 252 | H13: =D13*E13 -> 225 | I13: =H13*F13 -> 27 | J13: =H13+I13 -> 252 | K13: =G13-J13 -> 0 | L13: =IF(K13=0,"Verified","Discrepancy") -> Verified | M13: =IF(OR(A13="",B13="",C13="",D13<=0,E13<=0),"Review Required","Complete") -> Complete | N13: =IF(A13="","Missing Invoice ID",IF(COUNTIF($A$2:$A$151,A13)>1,"Duplicate","Unique")) -> Unique | O13: =IF(OR(A13="",N13="Missing Invoice ID"),"Missing Invoice ID",IF(N13="Duplicate","Duplicate - Investigate",IF(M13="Review Required","Incomplete - Review",IF(L13="Discrepancy","Amount Mismatch","Passed QC")))) -> Passed QC
A14: INV0013 | C14: Headphones | D14: 44 | E14: 1200 | F14: 0.18 | G14: 62304 | H14: =D14*E14 -> 52800 | I14: =H14*F14 -> 9504 | J14: =H14+I14 -> 62304 | K14: =G14-J14 -> 0 | L14: =IF(K14=0,"Verified","Discrepancy") -> Verified | M14: =IF(OR(A14="",B14="",C14="",D14<=0,E14<=0),"Review Required","Complete") -> Review Required | N14: =IF(A14="","Missing Invoice ID",IF(COUNTIF($A$2:$A$151,A14)>1,"Duplicate","Unique")) -> Unique | O14: =IF(OR(A14="",N14="Missing Invoice ID"),"Missing Invoice ID",IF(N14="Duplicate","Duplicate - Investigate",IF(M14="Review Required","Incomplete - Review",IF(L14="Discrepancy","Amount Mismatch","Passed QC")))) -> Incomplete - Review
A15: INV0014 | B15: Metro Wholesale | C15: Folders | D15: 26 | E15: 35 | F15: 0.12 | G15: 1019.2 | H15: =D15*E15 -> 910 | I15: =H15*F15 -> 109.2 | J15: =H15+I15 -> 1019.2 | K15: =G15-J15 -> 0 | L15: =IF(K15=0,"Verified","Discrepancy") -> Verified | M15: =IF(OR(A15="",B15="",C15="",D15<=0,E15<=0),"Review Required","Complete") -> Complete | N15: =IF(A15="","Missing Invoice ID",IF(COUNTIF($A$2:$A$151,A15)>1,"Duplicate","Unique")) -> Unique | O15: =IF(OR(A15="",N15="Missing Invoice ID"),"Missing Invoice ID",IF(N15="Duplicate","Duplicate - Investigate",IF(M15="Review Required","Incomplete - Review",IF(L15="Discrepancy","Amount Mismatch","Passed QC")))) -> Passed QC
A16: INV0015 | B16: Global Tech | C16: Desk Lamp | D16: 6 | E16: 900 | F16: 0.18 | G16: 6372 | H16: =D16*E16 -> 5400 | I16: =H16*F16 -> 972 | J16: =H16+I16 -> 6372 | K16: =G16-J16 -> 0 | L16: =IF(K16=0,"Verified","Discrepancy") -> Verified | M16: =IF(OR(A16="",B16="",C16="",D16<=0,E16<=0),"Review Required","Complete") -> Complete | N16: =IF(A16="","Missing Invoice ID",IF(COUNTIF($A$2:$A$151,A16)>1,"Duplicate","Unique")) -> Unique | O16: =IF(OR(A16="",N16="Missing Invoice ID"),"Missing Invoice ID",IF(N16="Duplicate","Duplicate - Investigate",IF(M16="Review Required","Incomplete - Review",IF(L16="Discrepancy","Amount Mismatch","Passed QC")))) -> Passed QC
A17: INV0016 | B17: Northstar Supplies | C17: Desk Lamp | D17: 2 | E17: 900 | F17: 0.18 | G17: 2124 | H17: =D17*E17 -> 1800 | I17: =H17*F17 -> 324 | J17: =H17+I17 -> 2124 | K17: =G17-J17 -> 0 | L17: =IF(K17=0,"Verified","Discrepancy") -> Verified | M17: =IF(OR(A17="",B17="",C17="",D17<=0,E17<=0),"Review Required","Complete") -> Complete | N17: =IF(A17="","Missing Invoice ID",IF(COUNTIF($A$2:$A$151,A17)>1,"Duplicate","Unique")) -> Unique | O17: =IF(OR(A17="",N17="Missing Invoice ID"),"Missing Invoice ID",IF(N17="Duplicate","Duplicate - Investigate",IF(M17="Review Required","Incomplete - Review",IF(L17="Discrepancy","Amount Mismatch","Passed QC")))) -> Passed QC
A18: INV0017 | B18: Evergreen Retail | C18: Files | D18: 36 | E18: 25 | F18: 0.12 | G18: 1008 | H18: =D18*E18 -> 900 | I18: =H18*F18 -> 108 | J18: =H18+I18 -> 1008 | K18: =G18-J18 -> 0 | L18: =IF(K18=0,"Verified","Discrepancy") -> Verified | M18: =IF(OR(A18="",B18="",C18="",D18<=0,E18<=0),"Review Required","Complete") -> Complete | N18: =IF(A18="","Missing Invoice ID",IF(COUNTIF($A$2:$A$151,A18)>1,"Duplicate","Unique")) -> Unique | O18: =IF(OR(A18="",N18="Missing Invoice ID"),"Missing Invoice ID",IF(N18="Duplicate","Duplicate - Investigate",IF(M18="Review Required","Incomplete - Review",IF(L18="Discrepancy","Amount Mismatch","Passed QC")))) -> Passed QC
A19: INV0018 | B19: XYZ Supplies | C19: USB Drive | D19: 3 | E19: 450 | F19: 0.18 | G19: 1593 | H19: =D19*E19 -> 1350 | I19: =H19*F19 -> 243 | J19: =H19+I19 -> 1593 | K19: =G19-J19 -> 0 | L19: =IF(K19=0,"Verified","Discrepancy") -> Verified | M19: =IF(OR(A19="",B19="",C19="",D19<=0,E19<=0),"Review Required","Complete") -> Complete | N19: =IF(A19="","Missing Invoice ID",IF(COUNTIF($A$2:$A$151,A19)>1,"Duplicate","Unique")) -> Unique | O19: =IF(OR(A19="",N19="Missing Invoice ID"),"Missing Invoice ID",IF(N19="Duplicate","Duplicate - Investigate",IF(M19="Review Required","Incomplete - Review",IF(L19="Discrepancy","Amount Mismatch","Passed QC")))) -> Passed QC
A20: INV0019 | B20: Brightline Distributors | C20: USB Drive | D20: 2 | E20: 450 | F20: 0.18 | G20: 1312 | H20: =D20*E20 -> 900 | I20: =H20*F20 -> 162 | J20: =H20+I20 -> 1062 | K20: =G20-J20 -> 250 | L20: =IF(K20=0,"Verified","Discrepancy") -> Discrepancy | M20: =IF(OR(A20="",B20="",C20="",D20<=0,E20<=0),"Review Required","Complete") -> Complete | N20: =IF(A20="","Missing Invoice ID",IF(COUNTIF($A$2:$A$151,A20)>1,"Duplicate","Unique")) -> Unique | O20: =IF(OR(A20="",N20="Missing Invoice ID"),"Missing Invoice ID",IF(N20="Duplicate","Duplicate - Investigate",IF(M20="Review Required","Incomplete - Review",IF(L20="Discrepancy","Amount Mismatch","Passed QC")))) -> Amount Mismatch
A21: INV0020 | B21: Citywide Products | C21: Keyboards | D21: 4 | E21: 800 | F21: 0.18 | G21: 3776 | H21: =D21*E21 -> 3200 | I21: =H21*F21 -> 576 | J21: =H21+I21 -> 3776 | K21: =G21-J21 -> 0 | L21: =IF(K21=0,"Verified","Discrepancy") -> Verified | M21: =IF(OR(A21="",B21="",C21="",D21<=0,E21<=0),"Review Required","Complete") -> Complete | N21: =IF(A21="","Missing Invoice ID",IF(COUNTIF($A$2:$A$151,A21)>1,"Duplicate","Unique")) -> Unique | O21: =IF(OR(A21="",N21="Missing Invoice ID"),"Missing Invoice ID",IF(N21="Duplicate","Duplicate - Investigate",IF(M21="Review Required","Incomplete - Review",IF(L21="Discrepancy","Amount Mismatch","Passed QC")))) -> Passed QC
A22: INV0021 | B22: Northstar Supplies | C22: Monitor | D22: 19 | E22: 6500 | F22: 0.18 | G22: 145730 | H22: =D22*E22 -> 123500 | I22: =H22*F22 -> 22230 | J22: =H22+I22 -> 145730 | K22: =G22-J22 -> 0 | L22: =IF(K22=0,"Verified","Discrepancy") -> Verified | M22: =IF(OR(A22="",B22="",C22="",D22<=0,E22<=0),"Review Required","Complete") -> Complete | N22: =IF(A22="","Missing Invoice ID",IF(COUNTIF($A$2:$A$151,A22)>1,"Duplicate","Unique")) -> Unique | O22: =IF(OR(A22="",N22="Missing Invoice ID"),"Missing Invoice ID",IF(N22="Duplicate","Duplicate - Investigate",IF(M22="Review Required","Incomplete - Review",IF(L22="Discrepancy","Amount Mismatch","Passed QC")))) -> Passed QC
A23: INV0022 | B23: XYZ Supplies | C23: Keyboards | D23: 27 | E23: 800 | F23: 0.18 | G23: 25488 | H23: =D23*E23 -> 21600 | I23: =H23*F23 -> 3888 | J23: =H23+I23 -> 25488 | K23: =G23-J23 -> 0 | L23: =IF(K23=0,"Verified","Discrepancy") -> Verified | M23: =IF(OR(A23="",B23="",C23="",D23<=0,E23<=0),"Review Required","Complete") -> Complete | N23: =IF(A23="","Missing Invoice ID",IF(COUNTIF($A$2:$A$151,A23)>1,"Duplicate","Unique")) -> Unique | O23: =IF(OR(A23="",N23="Missing Invoice ID"),"Missing Invoice ID",IF(N23="Duplicate","Duplicate - Investigate",IF(M23="Review Required","Incomplete - Review",IF(L23="Discrepancy","Amount Mismatch","Passed QC")))) -> Passed QC
A24: INV0023 | B24: Brightline Distributors | C24: Paper Clips | D24: 32 | E24: 60 | F24: 0.12 | G24: 2150.4 | H24: =D24*E24 -> 1920 | I24: =H24*F24 -> 230.4 | J24: =H24+I24 -> 2150.4 | K24: =G24-J24 -> 0 | L24: =IF(K24=0,"Verified","Discrepancy") -> Verified | M24: =IF(OR(A24="",B24="",C24="",D24<=0,E24<=0),"Review Required","Complete") -> Complete | N24: =IF(A24="","Missing Invoice ID",IF(COUNTIF($A$2:$A$151,A24)>1,"Duplicate","Unique")) -> Unique | O24: =IF(OR(A24="",N24="Missing Invoice ID"),"Missing Invoice ID",IF(N24="Duplicate","Duplicate - Investigate",IF(M24="Review Required","Incomplete - Review",IF(L24="Discrepancy","Amount Mismatch","Passed QC")))) -> Passed QC
A25: INV0024 | B25: Prime Office | C25: Printer Toner | D25: 0 | E25: 2200 | F25: 0.18 | G25: 88264 | H25: =D25*E25 -> 0 | I25: =H25*F25 -> 0 | J25: =H25+I25 -> 0 | K25: =G25-J25 -> 88264 | L25: =IF(K25=0,"Verified","Discrepancy") -> Discrepancy | M25: =IF(OR(A25="",B25="",C25="",D25<=0,E25<=0),"Review Required","Complete") -> Review Required | N25: =IF(A25="","Missing Invoice ID",IF(COUNTIF($A$2:$A$151,A25)>1,"Duplicate","Unique")) -> Unique | O25: =IF(OR(A25="",N25="Missing Invoice ID"),"Missing Invoice ID",IF(N25="Duplicate","Duplicate - Investigate",IF(M25="Review Required","Incomplete - Review",IF(L25="Discrepancy","Amount Mismatch","Passed QC")))) -> Incomplete - Review
A26: INV0025 | B26: Metro Wholesale | C26: Monitor | D26: 46 | E26: 6500 | F26: 0.18 | G26: 352820 | H26: =D26*E26 -> 299000 | I26: =H26*F26 -> 53820 | J26: =H26+I26 -> 352820 | K26: =G26-J26 -> 0 | L26: =IF(K26=0,"Verified","Discrepancy") -> Verified | M26: =IF(OR(A26="",B26="",C26="",D26<=0,E26<=0),"Review Required","Complete") -> Complete | N26: =IF(A26="","Missing Invoice ID",IF(COUNTIF($A$2:$A$151,A26)>1,"Duplicate","Unique")) -> Unique | O26: =IF(OR(A26="",N26="Missing Invoice ID"),"Missing Invoice ID",IF(N26="Duplicate","Duplicate - Investigate",IF(M26="Review Required","Incomplete - Review",IF(L26="Discrepancy","Amount Mismatch","Passed QC")))) -> Passed QC
... A31: INV0030 | B31: Evergreen Retail | C31: Keyboards | D31: 45 | E31: 800 | F31: 0.18 | G31: 42480 | H31: =D31*E31 -> 36000 | I31: =H31*F31 -> 6480 | J31: =H31+I31 -> 42480 | K31: =G31-J31 -> 0 | L31: =IF(K31=0,"Verified","Discrepancy") -> Verified | M31: =IF(OR(A31="",B31="",C31="",D31<=0,E31<=0),"Review Required","Complete") -> Complete | N31: =IF(A31="","Missing Invoice ID",IF(COUNTIF($A$2:$A$151,A31)>1,"Duplicate","Unique")) -> Unique | O31: =IF(OR(A31="",N31="Missing Invoice ID"),"Missing Invoice ID",IF(N31="Duplicate","Duplicate - Investigate",IF(M31="Review Required","Incomplete - Review",IF(L31="Discrepancy","Amount Mismatch","Passed QC")))) -> Passed QC
B32: Prime Office | D32: 49 | E32: 25 | F32: 0.12 | G32: 1372 | H32: =D32*E32 -> 1225 | I32: =H32*F32 -> 147 | J32: =H32+I32 -> 1372 | K32: =G32-J32 -> 0 | L32: =IF(K32=0,"Verified","Discrepancy") -> Verified | M32: =IF(OR(A32="",B32="",C32="",D32<=0,E32<=0),"Review Required","Complete") -> Review Required | N32: =IF(A32="","Missing Invoice ID",IF(COUNTIF($A$2:$A$151,A32)>1,"Duplicate","Unique")) -> Missing Invoice ID | O32: =IF(OR(A32="",N32="Missing Invoice ID"),"Missing Invoice ID",IF(N32="Duplicate","Duplicate - Investigate",IF(M32="Review Required","Incomplete - Review",IF(L32="Discrepancy","Amount Mismatch","Passed QC")))) -> Missing Invoice ID
A33: INV0032 | B33: Apex Business Solutions | C33: Whiteboard | D33: 10 | E33: 1800 | F33: 0.18 | G33: 21240 | H33: =D33*E33 -> 18000 | I33: =H33*F33 -> 3240 | J33: =H33+I33 -> 21240 | K33: =G33-J33 -> 0 | L33: =IF(K33=0,"Verified","Discrepancy") -> Verified | M33: =IF(OR(A33="",B33="",C33="",D33<=0,E33<=0),"Review Required","Complete") -> Complete | N33: =IF(A33="","Missing Invoice ID",IF(COUNTIF($A$2:$A$151,A33)>1,"Duplicate","Unique")) -> Unique | O33: =IF(OR(A33="",N33="Missing Invoice ID"),"Missing Invoice ID",IF(N33="Duplicate","Duplicate - Investigate",IF(M33="Review Required","Incomplete - Review",IF(L33="Discrepancy","Amount Mismatch","Passed QC")))) -> Passed QC
A34: INV0033 | B34: XYZ Supplies | C34: Keyboards | D34: 21 | E34: 800 | F34: 0.18 | G34: 19824 | H34: =D34*E34 -> 16800 | I34: =H34*F34 -> 3024 | J34: =H34+I34 -> 19824 | K34: =G34-J34 -> 0 | L34: =IF(K34=0,"Verified","Discrepancy") -> Verified | M34: =IF(OR(A34="",B34="",C34="",D34<=0,E34<=0),"Review Required","Complete") -> Complete | N34: =IF(A34="","Missing Invoice ID",IF(COUNTIF($A$2:$A$151,A34)>1,"Duplicate","Unique")) -> Unique | O34: =IF(OR(A34="",N34="Missing Invoice ID"),"Missing Invoice ID",IF(N34="Duplicate","Duplicate - Investigate",IF(M34="Review Required","Incomplete - Review",IF(L34="Discrepancy","Amount Mismatch","Passed QC")))) -> Passed QC
A35: INV0034 | B35: Brightline Distributors | C35: Folders | D35: 6 | E35: 35 | F35: 0.12 | G35: 235.2 | H35: =D35*E35 -> 210 | I35: =H35*F35 -> 25.2 | J35: =H35+I35 -> 235.2 | K35: =G35-J35 -> 0 | L35: =IF(K35=0,"Verified","Discrepancy") -> Verified | M35: =IF(OR(A35="",B35="",C35="",D35<=0,E35<=0),"Review Required","Complete") -> Complete | N35: =IF(A35="","Missing Invoice ID",IF(COUNTIF($A$2:$A$151,A35)>1,"Duplicate","Unique")) -> Unique | O35: =IF(OR(A35="",N35="Missing Invoice ID"),"Missing Invoice ID",IF(N35="Duplicate","Duplicate - Investigate",IF(M35="Review Required","Incomplete - Review",IF(L35="Discrepancy","Amount Mismatch","Passed QC")))) -> Passed QC
A36: INV0035 | B36: ABC Traders | C36: Extension Board | D36: 37 | E36: 550 | F36: 0.18 | G36: 24013 | H36: =D36*E36 -> 20350 | I36: =H36*F36 -> 3663 | J36: =H36+I36 -> 24013 | K36: =G36-J36 -> 0 | L36: =IF(K36=0,"Verified","Discrepancy") -> Verified | M36: =IF(OR(A36="",B36="",C36="",D36<=0,E36<=0),"Review Required","Complete") -> Complete | N36: =IF(A36="","Missing Invoice ID",IF(COUNTIF($A$2:$A$151,A36)>1,"Duplicate","Unique")) -> Unique | O36: =IF(OR(A36="",N36="Missing Invoice ID"),"Missing Invoice ID",IF(N36="Duplicate","Duplicate - Investigate",IF(M36="Review Required","Incomplete - Review",IF(L36="Discrepancy","Amount Mismatch","Passed QC")))) -> Passed QC
A37: INV0036 | B37: Brightline Distributors | C37: Whiteboard | D37: 5 | E37: 1800 | F37: 0.18 | G37: 10720 | H37: =D37*E37 -> 9000 | I37: =H37*F37 -> 1620 | J37: =H37+I37 -> 10620 | K37: =G37-J37 -> 100 | L37: =IF(K37=0,"Verified","Discrepancy") -> Discrepancy | M37: =IF(OR(A37="",B37="",C37="",D37<=0,E37<=0),"Review Required","Complete") -> Complete | N37: =IF(A37="","Missing Invoice ID",IF(COUNTIF($A$2:$A$151,A37)>1,"Duplicate","Unique")) -> Unique | O37: =IF(OR(A37="",N37="Missing Invoice ID"),"Missing Invoice ID",IF(N37="Duplicate","Duplicate - Investigate",IF(M37="Review Required","Incomplete - Review",IF(L37="Discrepancy","Amount Mismatch","Passed QC")))) -> Amount Mismatch
A38: INV0037 | B38: Metro Wholesale | C38: Headphones | D38: 7 | E38: 1200 | F38: 0.18 | G38: 9912 | H38: =D38*E38 -> 8400 | I38: =H38*F38 -> 1512 | J38: =H38+I38 -> 9912 | K38: =G38-J38 -> 0 | L38: =IF(K38=0,"Verified","Discrepancy") -> Verified | M38: =IF(OR(A38="",B38="",C38="",D38<=0,E38<=0),"Review Required","Complete") -> Complete | N38: =IF(A38="","Missing Invoice ID",IF(COUNTIF($A$2:$A$151,A38)>1,"Duplicate","Unique")) -> Unique | O38: =IF(OR(A38="",N38="Missing Invoice ID"),"Missing Invoice ID",IF(N38="Duplicate","Duplicate - Investigate",IF(M38="Review Required","Incomplete - Review",IF(L38="Discrepancy","Amount Mismatch","Passed QC")))) -> Passed QC
A39: INV0038 | B39: Metro Wholesale | C39: Keyboards | D39: 18 | E39: 800 | F39: 0.18 | G39: 16992 | H39: =D39*E39 -> 14400 | I39: =H39*F39 -> 2592 | J39: =H39+I39 -> 16992 | K39: =G39-J39 -> 0 | L39: =IF(K39=0,"Verified","Discrepancy") -> Verified | M39: =IF(OR(A39="",B39="",C39="",D39<=0,E39<=0),"Review Required","Complete") -> Complete | N39: =IF(A39="","Missing Invoice ID",IF(COUNTIF($A$2:$A$151,A39)>1,"Duplicate","Unique")) -> Unique | O39: =IF(OR(A39="",N39="Missing Invoice ID"),"Missing Invoice ID",IF(N39="Duplicate","Duplicate - Investigate",IF(M39="Review Required","Incomplete - Review",IF(L39="Discrepancy","Amount Mismatch","Passed QC")))) -> Passed QC
A40: INV0039 | B40: Evergreen Retail | C40: Files | D40: 29 | E40: 25 | F40: 0.12 | G40: 812 | H40: =D40*E40 -> 725 | I40: =H40*F40 -> 87 | J40: =H40+I40 -> 812 | K40: =G40-J40 -> 0 | L40: =IF(K40=0,"Verified","Discrepancy") -> Verified | M40: =IF(OR(A40="",B40="",C40="",D40<=0,E40<=0),"Review Required","Complete") -> Complete | N40: =IF(A40="","Missing Invoice ID",IF(COUNTIF($A$2:$A$151,A40)>1,"Duplicate","Unique")) -> Unique | O40: =IF(OR(A40="",N40="Missing Invoice ID"),"Missing Invoice ID",IF(N40="Duplicate","Duplicate - Investigate",IF(M40="Review Required","Incomplete - Review",IF(L40="Discrepancy","Amount Mismatch","Passed QC")))) -> Passed QC
A41: INV0040 | B41: XYZ Supplies | C41: Calculator | D41: 22 | E41: 650 | F41: 0.18 | G41: 16874 | H41: =D41*E41 -> 14300 | I41: =H41*F41 -> 2574 | J41: =H41+I41 -> 16874 | K41: =G41-J41 -> 0 | L41: =IF(K41=0,"Verified","Discrepancy") -> Verified | M41: =IF(OR(A41="",B41="",C41="",D41<=0,E41<=0),"Review Required","Complete") -> Complete | N41: =IF(A41="","Missing Invoice ID",IF(COUNTIF($A$2:$A$151,A41)>1,"Duplicate","Unique")) -> Unique | O41: =IF(OR(A41="",N41="Missing Invoice ID"),"Missing Invoice ID",IF(N41="Duplicate","Duplicate - Investigate",IF(M41="Review Required","Incomplete - Review",IF(L41="Discrepancy","Amount Mismatch","Passed QC")))) -> Passed QC
A42: INV0041 | B42: Global Tech | C42: Pens | D42: 19 | E42: 10 | F42: 0.18 | G42: 224.2 | H42: =D42*E42 -> 190 | I42: =H42*F42 -> 34.2 | J42: =H42+I42 -> 224.2 | K42: =G42-J42 -> 0 | L42: =IF(K42=0,"Verified","Discrepancy") -> Verified | M42: =IF(OR(A42="",B42="",C42="",D42<=0,E42<=0),"Review Required","Complete") -> Complete | N42: =IF(A42="","Missing Invoice ID",IF(COUNTIF($A$2:$A$151,A42)>1,"Duplicate","Unique")) -> Unique | O42: =IF(OR(A42="",N42="Missing Invoice ID"),"Missing Invoice ID",IF(N42="Duplicate","Duplicate - Investigate",IF(M42="Review Required","Incomplete - Review",IF(L42="Discrepancy","Amount Mismatch","Passed QC")))) -> Passed QC
A43: INV0042 | C43: Office Chairs | D43: 2 | E43: 2500 | F43: 0.18 | G43: 5900 | H43: =D43*E43 -> 5000 | I43: =H43*F43 -> 900 | J43: =H43+I43 -> 5900 | K43: =G43-J43 -> 0 | L43: =IF(K43=0,"Verified","Discrepancy") -> Verified | M43: =IF(OR(A43="",B43="",C43="",D43<=0,E43<=0),"Review Required","Complete") -> Review Required | N43: =IF(A43="","Missing Invoice ID",IF(COUNTIF($A$2:$A$151,A43)>1,"Duplicate","Unique")) -> Unique | O43: =IF(OR(A43="",N43="Missing Invoice ID"),"Missing Invoice ID",IF(N43="Duplicate","Duplicate - Investigate",IF(M43="Review Required","Incomplete - Review",IF(L43="Discrepancy","Amount Mismatch","Passed QC")))) -> Incomplete - Review
A44: INV0043 | B44: Northstar Supplies | C44: Filing Cabinet | D44: 31 | E44: 7200 | F44: 0.18 | G44: 263376 | H44: =D44*E44 -> 223200 | I44: =H44*F44 -> 40176 | J44: =H44+I44 -> 263376 | K44: =G44-J44 -> 0 | L44: =IF(K44=0,"Verified","Discrepancy") -> Verified | M44: =IF(OR(A44="",B44="",C44="",D44<=0,E44<=0),"Review Required","Complete") -> Complete | N44: =IF(A44="","Missing Invoice ID",IF(COUNTIF($A$2:$A$151,A44)>1,"Duplicate","Unique")) -> Unique | O44: =IF(OR(A44="",N44="Missing Invoice ID"),"Missing Invoice ID",IF(N44="Duplicate","Duplicate - Investigate",IF(M44="Review Required","Incomplete - Review",IF(L44="Discrepancy","Amount Mismatch","Passed QC")))) -> Passed QC
...

Sheet QC_summary
A1: INVOICE QUALITY SUMMARY
D2: Invoice Status | E2: Count | G2: Final QC Status | H2: Count
A3: Total Invoices | B3: =COUNTA(tbl_invoices!A2:A151) -> 148 | D3: Verified | E3: =COUNTIF(tbl_invoices!L2:L151,"Verified") -> 132 | G3: Passed QC | H3: =B14 -> 118
A4: Verified Invoices | B4: =COUNTIF(tbl_invoices!L2:L151,"Verified") -> 132 | D4: Discrepancy | E4: =COUNTIF(tbl_invoices!L2:L151,"Discrepancy") -> 18 | G4: Amount Mismatch | H4: =B15 -> 14
A5: Invoices with Discrepancies | B5: =COUNTIF(tbl_invoices!L2:L151,"Discrepancy") -> 18 | D5: Review Required | E5: =COUNTIF(tbl_invoices!M2:M151,"Review Required") -> 12 | G5: Incomplete - Review | H5: =B16 -> 10
A6: Records requiring Review | B6: =COUNTIF(tbl_invoices!M2:M151,"Review Required") -> 12 | G6: Duplicate - Investigate | H6: =B17 -> 6
A7: Complete Records | B7: =COUNTIF(tbl_invoices!M2:M151,"Complete") -> 138 | G7: Missing Invoice ID | H7: =B18 -> 2
A8: Verification Rate | B8: =IFERROR(B4/B3,0) -> 0.89189189
A9: Data completion rate | B9: =IFERROR(B7/B3,0) -> 0.93243243
A10: Duplicate Invoice Records | B10: =COUNTIF(tbl_invoices!N2:N151,"Duplicate") -> 6
A11: Missing Invoice IDs | B11: =COUNTIF(tbl_invoices!N2:N151,"Missing Invoice ID") -> 2
A13: FINAL QC SUMMARY
A14: Passed QC | B14: =COUNTIF(tbl_invoices!O2:O151,"Passed QC") -> 118
A15: Amount Mismatch | B15: =COUNTIF(tbl_invoices!O2:O151,"Amount Mismatch") -> 14
A16: Incomplete Review | B16: =COUNTIF(tbl_invoices!O2:O151,"Incomplete - Review") -> 10
A17: Duplicate-Investigate | B17: =COUNTIF(tbl_invoices!O2:O151,"Duplicate - Investigate") -> 6
A18: Missing Invoice ID | B18: =COUNTIF(tbl_invoices!O2:O151,"Missing Invoice ID") -> 2
A19: Final QC Pass Rate | B19: =IFERROR(B14/B3,0) -> 0.7972973

Sheet Invoice_dashboard
A1: Invoice Verification & Quality Dashboard
A3: TOTAL INVOICES | C3: VERIFIED INVOICES | E3: DISCREPANCIES | G3: RECORDS TO REVIEW
A4: =QC_summary!B3 -> 148 | C4: =QC_summary!B4 -> 132 | E4: =QC_summary!B5 -> 18 | G4: =QC_summary!B6 -> 12
A7: VERIFICATION RATE | C7: DATA COMPLETENESS RATE | E7: Final QC PassRate
A8: =QC_summary!B8 -> 0.89189189 | C8: =QC_summary!B9 -> 0.93243243 | E8: =QC_summary!B19 -> 0.7972973

Sheet Project_Overview
A1: Raw Invoice Dataset — 150 Rows
A2: Purpose | B2: Use this as the starting dataset for Project 1. Calculate all derived fields yourself in Excel.
A3: Raw fields only | B3: Invoice_ID, Vendor, Item_Description, Quantity, Unit_Price, Tax_Rate, Extracted_Total.
A4: No pre-calculations | B4: This workbook contains no Subtotal, Expected_Tax, Expected_Total, Difference, Verification_Status, or Data_Quality_Status formulas.
A5: Practice note | B5: Some records intentionally contain discrepancies or missing/invalid values. Identify these through your own formulas and checks.
A6: Data note | B6: All records are simulated for practice, not real invoices.
B10: PROJECT OVERVIEW
A11: Stage | B11: What you did | C11: Excel skills demonstrated
A12: 1. Data preparation | B12: Organized 150 invoice records into an Excel Table | C12: Tables, structured data
A13: 2. Calculations | B13: Calculated subtotal, expected tax and expected total | C13: Arithmetic formulas
A14: 3. Reconciliation | B14: Compared extracted totals with expected totals | C14: Difference calculations
A15: 4. Verification | B15: Classified invoices as verified or discrepant | C15: IF
A16: 5. Data quality | B16: Flagged missing fields and invalid quantities or prices | C16: IF, OR
A17: 6. Duplicate detection | B17: Flagged repeated invoice IDs | C17: COUNTIF
A18: 7. Final classification | B18: Assigned a final QC status to each record | C18: Nested IF, OR
A19: 8. Reporting | B19: Summarized the results and built charts | C19: COUNTIF, cell references, charts
